/*
 * exception.cpp
 *
 *  Created on: 13-Nov-2017
 *      Author: ee205237
 */
#include<iostream>
using namespace std;
int main()
{
	int a;
	int x;
	int i=10;
	try
	{
		if(i/0)
		{
			throw x;
		}
	}
	catch(int x)
	{
		cout<<"DevideByZero"
	}

}




