/*
 * exception.cpp
 *
 *  Created on: 13-Nov-2017
 *      Author: ee205237
 */
#include<iostream>
using namespace std;
void devide(int a, int b);
int main()
{
	int a=1,b=0;
	int x;
	int  result=0;
	int  i=10;
	result=devide(2,0);
}
void devide(int a, int b)
{
	int result;
	try
	{
		if(b==0)
		{
			throw x;
		}
		result =a/b;
	}
	catch(int x)
	{
		cout<<"DevideByZero";
	}
}

//diffrent case:
	//-
	//-
	//-




