/*
 * exception.cpp
 *
 *  Created on: 13-Nov-2017
 *      Author: ee205237
 */
#include<iostream>
using namespace std;
int main()
{
	int a=1,b=0;
	int x;
	int result;

	int i=10;
	try
	{
		if(1)
		{
			if(b==0)
			{
				throw x;
			}
			result =a/b;
		}
	}
	catch(int x)
	{
		cout<<"DevideByZero";
	}

}

//diffrent case:
	//-
	//-
	//-




